Workbook

Sheet README
A1: Asia Cup Complete Dataset (2022 + 2025)
A3: Scope | C3: Asia Cup 2022 (13 matches, from your xlsx) + Asia Cup 2025 (19 matches, from the downloaded CSV) = 32 T20I matches.
A4: Sheets | C4: Master Dataset · 2025 Scorecard Detail · Team Records · Tournament Summary · Venue Analysis · Player of the Match
A5: Colour code | C5: Navy header = original columns from your xlsx / CSV. Brown header = new identifier columns. Green header = derived columns (live formulas).
A7: Changes made to your original data
C8: • Dates 2022: matches 5–13 had day and month swapped (e.g. 1 Sep stored as 9 Jan). All dates rebuilt as real dates and checked against the Day column.
C9: • Match 2 (India v Pakistan, 28 Aug 2022): Toss Winner changed from Pakistan to India. India won the toss and chose to field, which is also what makes Pakistan (Team 1) the side batting first.
C10: • Group "Super four" standardised to "Super Four"; boundary lengths, wind speed stored as numbers (displayed as 65M, 12 km/h); humidity shown as %.
C11: • Header row simplified: the merged title row is replaced by a Series column; the blank spacer column and the leading space in " TV Umpire" removed.
C12: • 2025 start times: the CSV says "6:00 PM LOCAL" but the ACC moved 18 of 19 matches to 6:30 PM GST (UAE v Oman, 15 Sep, was 4 PM GST). Written in your 2022 style with BST (GST + 1 hr).
A14: Known gaps (not invented)
C15: • 2025 weather and pitch were researched match by match (see the Weather & Pitch Source column). Condition = Wisden match-page weather where available, otherwise a pre-match forecast marked "(forecast)". Temperature, humidity and wind are pre-match FORECASTS from news previews, not measured readings, and are filled only where a source gave a figure.
C16: • Still blank for 2025: humidity (except Matches 6 and 11), wind speed (except Matches 6 and 16), wind direction, and weather condition for Matches 5 and 15. No source was found for these.
C17: • 2025 pitch notes are written from previews, toss reports and expert pitch reports, so they describe the expected or reported behaviour, not a post-match measurement. Match 14 uses a venue-level description because no match-specific report was found.
C18: • Boundary lengths: Dubai values reused from 2022 (same ground). Sheikh Zayed Stadium boundaries could not be found from a reliable source, so they are blank. Pitch length 20.12 m and width 3.05 m are the standard values.
C19: • Reserved Umpire is blank for 2025 (not in CSV). Playing XI, batting/bowling cards, fall of wickets, fours/sixes exist for 2025 only.
C20: • Super Over tie (2025 Match 18, India v Sri Lanka): Team 1 Run = Team 2 Run = 202; winner recorded as India, Won by = "Super Over".
A22: Derived columns in Master Dataset (formulas)
A23: Batting First / Second | C23: From toss winner and toss decision.
A24: 1st / 2nd Innings Score | C24: Runs of the team that batted first / second.
A25: Match Loser | C25: The team that did not win.
A26: Result Type | C26: "Tie (Super Over)" if both scores are level, otherwise "Normal".
A27: Winner Batted | C27: Batting First, Chasing, or Super Over.
A28: Toss Winner Won Match | C28: Yes / No.
A29: Margin Type / Value | C29: Parsed from "Won by": Runs or Wickets and the number.
A30: Total Match Runs / Run Difference | C30: Both teams combined / absolute gap.
A31: Total Powerplay Runs, Total Extras | C31: Both teams combined.
A32: Fixture Key | C32: Series|Stage, used by the summary sheets to find the final.
A34: Sources
C35: • Asia Cup 2022: your asia_cup_dataset.xlsx; toss for Match 2 checked against ESPNcricinfo / Wisden / Arab News match reports.
C36: • Asia Cup 2025: asia_cup_2025_complete_dataset.csv (as supplied); start times checked against the Emirates Cricket Board / ACC announcement.

Sheet Master Dataset
A1: Match ID | B1: Series | C1: Year | D1: Match Number | E1: Match Label | F1: Date | G1: Group | H1: Stage | I1: Day | J1: Venue | K1: City | L1: Time | M1: Format | N1: Straight Boundary Length | O1: Square Boundary Length | P1: Mid Wicket Boundary Length | Q1: Wicket-to-Wicket Length | R1: Pitch Width | S1: Temperature | T1: Humidity | U1: Condition | V1: Wind Speed | W1: Wind Direction | X1: Pitch Condition | Y1: Team 1 | Z1: Team 2 | AA1: Toss Winner | AB1: Elected First | AC1: Powerplay Run Team 1 | AD1: Powerplay Run Team 2 | AE1: Team 1 Run | AF1: Team 2 Run | AG1: Match Winner | AH1: Player of The Match | AI1: Team 1 Extras | AJ1: Team 2 Extras | AK1: Won by | AL1: Umpire 1 | AM1: Umpire 2 | AN1: TV Umpire | AO1: Reserved Umpire | AP1: Match Referee | AQ1: Weather & Pitch Source | AR1: Batting First | AS1: Batting Second | AT1: 1st Innings Score | AU1: 2nd Innings Score | AV1: Match Loser | AW1: Result Type | AX1: Winner Batted | AY1: Toss Winner Won Match | AZ1: Margin Type | BA1: Margin Value | BB1: Total Match Runs | BC1: Run Difference | BD1: Total Powerplay Runs | BE1: Total Extras | BF1: Fixture Key
A2: AC2022-01 | B2: Asia Cup 2022 | C2: 2022 | D2: 1 | E2: 1st Match, Group B | F2: 44800 | G2: B | H2: Group Stage | I2: Saturday | J2: Dubai International Cricket Stadium | K2: Dubai | L2: 6 PM (GST), 8 PM (BST) | M2: T20I | N2: 65 | O2: 80 | P2: 75 | Q2: 20.12 | R2: 3.05 | S2: 36 deg C | T2: 0.35 | U2: Passing Clouds | V2: 12 | W2: North East | X2: Two-paced - there was the occasional low bounce | Y2: Sri Lanka | Z2: Afghanistan | AA2: Afghanistan | AB2: Bowl | AC2: 41 | AD2: 83 | AE2: 105 | AF2: 106 | AG2: Afghanistan | AH2: Fazalhaq Farooqi | AI2: 6 | AJ2: 12 | AK2: 8 Wickets | AL2: Ahsan Raza | AM2: Anil Chaudhary | AN2: Jayaraman Madanagopal | AO2: Asif Yaqoob | AP2: Jeff Crowe | AQ2: Original dataset (user-supplied) | AR2: =IF(AB2="Bat",AA2,IF(AA2=Y2,Z2,Y2)) -> Sri Lanka | AS2: =IF(AR2=Y2,Z2,Y2) -> Afghanistan | AT2: =IF(AR2=Y2,AE2,AF2) -> 105 | AU2: =IF(AR2=Y2,AF2,AE2) -> 106 | AV2: =IF(AG2=Y2,Z2,Y2) -> Sri Lanka | AW2: =IF(AE2=AF2,"Tie (Super Over)","Normal") -> Normal | AX2: =IF(AW2<>"Normal","Super Over",IF(AG2=AR2,"Batting First","Chasing")) -> Chasing | AY2: =IF(AA2=AG2,"Yes","No") -> Yes | AZ2: =IF(ISNUMBER(SEARCH("Wicket",AK2)),"Wickets",IF(ISNUMBER(SEARCH("Run",AK2)),"Runs","Super Over")) -> Wickets | BA2: =IF(AZ2="Super Over","",VALUE(LEFT(AK2,FIND(" ",AK2)-1))) -> 8 | BB2: =AE2+AF2 -> 211 | BC2: =ABS(AE2-AF2) -> 1 | BD2: =AC2+AD2 -> 124 | BE2: =AI2+AJ2 -> 18 | BF2: =B2&"|"&H2 -> Asia Cup 2022|Group Stage
A3: AC2022-02 | B3: Asia Cup 2022 | C3: 2022 | D3: 2 | E3: 2nd Match, Group A | F3: 44801 | G3: A | H3: Group Stage | I3: Sunday | J3: Dubai International Cricket Stadium | K3: Dubai | L3: 6 PM (GST), 8 PM (BST) | M3: T20I | N3: 65 | O3: 80 | P3: 75 | Q3: 20.12 | R3: 3.05 | S3: 35 / 33 deg C | T3: 0.5 | U3: Passing Clouds | V3: 12 | W3: East North East | X3: A balanced yet challenging surface with a mix of steep bounce, tackiness, and late dew | Y3: Pakistan | Z3: India | AA3: India | AB3: Bowl | AC3: 43 | AD3: 38 | AE3: 147 | AF3: 148 | AG3: India | AH3: Hardik Pandya | AI3: 5 | AJ3: 14 | AK3: 5 Wickets | AL3: Masudur Rahman | AM3: Ruchira Palliyaguruge | AN3: Raveendra Wimalasiri | AO3: Gazi Sohel | AP3: Jeff Crowe | AQ3: Original dataset (user-supplied) | AR3: =IF(AB3="Bat",AA3,IF(AA3=Y3,Z3,Y3)) -> Pakistan | AS3: =IF(AR3=Y3,Z3,Y3) -> India | AT3: =IF(AR3=Y3,AE3,AF3) -> 147 | AU3: =IF(AR3=Y3,AF3,AE3) -> 148 | AV3: =IF(AG3=Y3,Z3,Y3) -> Pakistan | AW3: =IF(AE3=AF3,"Tie (Super Over)","Normal") -> Normal | AX3: =IF(AW3<>"Normal","Super Over",IF(AG3=AR3,"Batting First","Chasing")) -> Chasing | AY3: =IF(AA3=AG3,"Yes","No") -> Yes | AZ3: =IF(ISNUMBER(SEARCH("Wicket",AK3)),"Wickets",IF(ISNUMBER(SEARCH("Run",AK3)),"Runs","Super Over")) -> Wickets | BA3: =IF(AZ3="Super Over","",VALUE(LEFT(AK3,FIND(" ",AK3)-1))) -> 5 | BB3: =AE3+AF3 -> 295 | BC3: =ABS(AE3-AF3) -> 1 | BD3: =AC3+AD3 -> 81 | BE3: =AI3+AJ3 -> 19 | BF3: =B3&"|"&H3 -> Asia Cup 2022|Group Stage
A4: AC2022-03 | B4: Asia Cup 2022 | C4: 2022 | D4: 3 | E4: 3rd Match, Group B | F4: 44803 | G4: B | H4: Group Stage | I4: Tuesday | J4: Sharjah Cricket Stadium | K4: Sharjah | L4: 6 PM (GST), 8 PM (BST) | M4: T20I | N4: 58 | O4: 57 | P4: 65 | Q4: 20.12 | R4: 3.05 | S4: 37 / 33 deg C | T4: 0.45 | U4: Passing Clouds | V4: 11 | W4: North East | X4: A smallish ground with a flat pitch. Looks amazing to bat on | Y4: Bangladesh | Z4: Afghanistan | AA4: Bangladesh | AB4: Bat | AC4: 28 | AD4: 29 | AE4: 127 | AF4: 131 | AG4: Afghanistan | AH4: Mujeeb Ur Rahman | AI4: 5 | AJ4: 4 | AK4: 7 Wickets | AL4: Asif Yaqoob | AM4: Jayaraman Madanagopal | AN4: Anil Chaudhary | AO4: Ahsan Raza | AP4: Jeff Crowe | AQ4: Original dataset (user-supplied) | AR4: =IF(AB4="Bat",AA4,IF(AA4=Y4,Z4,Y4)) -> Bangladesh | AS4: =IF(AR4=Y4,Z4,Y4) -> Afghanistan | AT4: =IF(AR4=Y4,AE4,AF4) -> 127 | AU4: =IF(AR4=Y4,AF4,AE4) -> 131 | AV4: =IF(AG4=Y4,Z4,Y4) -> Bangladesh | AW4: =IF(AE4=AF4,"Tie (Super Over)","Normal") -> Normal | AX4: =IF(AW4<>"Normal","Super Over",IF(AG4=AR4,"Batting First","Chasing")) -> Chasing | AY4: =IF(AA4=AG4,"Yes","No") -> No | AZ4: =IF(ISNUMBER(SEARCH("Wicket",AK4)),"Wickets",IF(ISNUMBER(SEARCH("Run",AK4)),"Runs","Super Over")) -> Wickets | BA4: =IF(AZ4="Super Over","",VALUE(LEFT(AK4,FIND(" ",AK4)-1))) -> 7 | BB4: =AE4+AF4 -> 258 | BC4: =ABS(AE4-AF4) -> 4 | BD4: =AC4+AD4 -> 57 | BE4: =AI4+AJ4 -> 9 | BF4: =B4&"|"&H4 -> Asia Cup 2022|Group Stage
A5: AC2022-04 | B5: Asia Cup 2022 | C5: 2022 | D5: 4 | E5: 4th Match, Group A | F5: 44804 | G5: A | H5: Group Stage | I5: Wednesday | J5: Dubai International Cricket Stadium | K5: Dubai | L5: 6 PM (GST), 8 PM (BST) | M5: T20I | N5: 65 | O5: 80 | P5: 75 | Q5: 20.12 | R5: 3.05 | S5: 35 / 34 deg C | T5: 0.61 | U5: Clear | V5: 12 | W5: North North West | X5: All the grass is in clusters, which means the ball will definitely seam around | Y5: India | Z5: Hong Kong | AA5: Hong Kong | AB5: Bowl | AC5: 44 | AD5: 51 | AE5: 192 | AF5: 152 | AG5: India | AH5: Suryakumar Yadav | AI5: 8 | AJ5: 6 | AK5: 40 Runs | AL5: Ahsan Raza | AM5: Gazi Sohel | AN5: Asif Yaqoob | AO5: Ahmad Shah Pakteen | AP5: Jeff Crowe | AQ5: Original dataset (user-supplied) | AR5: =IF(AB5="Bat",AA5,IF(AA5=Y5,Z5,Y5)) -> India | AS5: =IF(AR5=Y5,Z5,Y5) -> Hong Kong | AT5: =IF(AR5=Y5,AE5,AF5) -> 192 | AU5: =IF(AR5=Y5,AF5,AE5) -> 152 | AV5: =IF(AG5=Y5,Z5,Y5) -> Hong Kong | AW5: =IF(AE5=AF5,"Tie (Super Over)","Normal") -> Normal | AX5: =IF(AW5<>"Normal","Super Over",IF(AG5=AR5,"Batting First","Chasing")) -> Batting First | AY5: =IF(AA5=AG5,"Yes","No") -> No | AZ5: =IF(ISNUMBER(SEARCH("Wicket",AK5)),"Wickets",IF(ISNUMBER(SEARCH("Run",AK5)),"Runs","Super Over")) -> Runs | BA5: =IF(AZ5="Super Over","",VALUE(LEFT(AK5,FIND(" ",AK5)-1))) -> 40 | BB5: =AE5+AF5 -> 344 | BC5: =ABS(AE5-AF5) -> 40 | BD5: =AC5+AD5 -> 95 | BE5: =AI5+AJ5 -> 14 | BF5: =B5&"|"&H5 -> Asia Cup 2022|Group Stage
A6: AC2022-05 | B6: Asia Cup 2022 | C6: 2022 | D6: 5 | E6: 5th Match, Group B | F6: 44805 | G6: B | H6: Group Stage | I6: Thursday | J6: Dubai International Cricket Stadium | K6: Dubai | L6: 6 PM (GST), 8 PM (BST) | M6: T20I | N6: 65 | O6: 80 | P6: 75 | Q6: 20.12 | R6: 3.05 | S6: 35 / 33 deg C | T6: 0.65 | U6: Passing Clouds | V6: 13 | W6: North North West | X6: The match will be played on a used surface, which means it might be a little more spin-friendly than tracks | Y6: Bangladesh | Z6: Sri Lanka | AA6: Sri Lanka | AB6: Bowl | AC6: 55 | AD6: 48 | AE6: 183 | AF6: 184 | AG6: Sri Lanka | AH6: Kusal Mendis | AI6: 10 | AJ6: 17 | AK6: 2 Wickets | AL6: Ahmad Shah Pakteen | AM6: Anil Chaudhary | AN6: Bismillah Jan Shinwari | AO6: Jayaraman Madanagopal | AP6: Jeff Crowe | AQ6: Original dataset (user-supplied) | AR6: =IF(AB6="Bat",AA6,IF(AA6=Y6,Z6,Y6)) -> Bangladesh | AS6: =IF(AR6=Y6,Z6,Y6) -> Sri Lanka | AT6: =IF(AR6=Y6,AE6,AF6) -> 183 | AU6: =IF(AR6=Y6,AF6,AE6) -> 184 | AV6: =IF(AG6=Y6,Z6,Y6) -> Bangladesh | AW6: =IF(AE6=AF6,"Tie (Super Over)","Normal") -> Normal | AX6: =IF(AW6<>"Normal","Super Over",IF(AG6=AR6,"Batting First","Chasing")) -> Chasing | AY6: =IF(AA6=AG6,"Yes","No") -> Yes | AZ6: =IF(ISNUMBER(SEARCH("Wicket",AK6)),"Wickets",IF(ISNUMBER(SEARCH("Run",AK6)),"Runs","Super Over")) -> Wickets | BA6: =IF(AZ6="Super Over","",VALUE(LEFT(AK6,FIND(" ",AK6)-1))) -> 2 | BB6: =AE6+AF6 -> 367 | BC6: =ABS(AE6-AF6) -> 1 | BD6: =AC6+AD6 -> 103 | BE6: =AI6+AJ6 -> 27 | BF6: =B6&"|"&H6 -> Asia Cup 2022|Group Stage
A7: AC2022-06 | B7: Asia Cup 2022 | C7: 2022 | D7: 6 | E7: 6th Match, Group A | F7: 44806 | G7: A | H7: Group Stage | I7: Friday | J7: Sharjah Cricket Stadium | K7: Sharjah | L7: 6 PM (GST), 8 PM (BST) | M7: T20I | N7: 58 | O7: 57 | P7: 65 | Q7: 20.12 | R7: 3.05 | S7: 37 / 33 deg C | T7: 0.46 | U7: Clear | V7: 10 | W7: North North West | X7: Slow and low, offering short boundaries but favoring spinners and disciplined bowlers over heavy hitters | Y7: Pakistan | Z7: Hong Kong | AA7: Hong Kong | AB7: Bowl | AC7: 40 | AD7: 19 | AE7: 193 | AF7: 38 | AG7: Pakistan | AH7: Mohammad Rizwan | AI7: 18 | AJ7: 10 | AK7: 155 Runs | AL7: Raveendra Wimalasiri | AM7: Ruchira Palliyaguruge | AN7: Masudur Rahman | AO7: Bismillah Jan Shinwari | AP7: Jeff Crowe | AQ7: Original dataset (user-supplied) | AR7: =IF(AB7="Bat",AA7,IF(AA7=Y7,Z7,Y7)) -> Pakistan | AS7: =IF(AR7=Y7,Z7,Y7) -> Hong Kong | AT7: =IF(AR7=Y7,AE7,AF7) -> 193 | AU7: =IF(AR7=Y7,AF7,AE7) -> 38 | AV7: =IF(AG7=Y7,Z7,Y7) -> Hong Kong | AW7: =IF(AE7=AF7,"Tie (Super Over)","Normal") -> Normal | AX7: =IF(AW7<>"Normal","Super Over",IF(AG7=AR7,"Batting First","Chasing")) -> Batting First | AY7: =IF(AA7=AG7,"Yes","No") -> No | AZ7: =IF(ISNUMBER(SEARCH("Wicket",AK7)),"Wickets",IF(ISNUMBER(SEARCH("Run",AK7)),"Runs","Super Over")) -> Runs | BA7: =IF(AZ7="Super Over","",VALUE(LEFT(AK7,FIND(" ",AK7)-1))) -> 155 | BB7: =AE7+AF7 -> 231 | BC7: =ABS(AE7-AF7) -> 155 | BD7: =AC7+AD7 -> 59 | BE7: =AI7+AJ7 -> 28 | BF7: =B7&"|"&H7 -> Asia Cup 2022|Group Stage
A8: AC2022-07 | B8: Asia Cup 2022 | C8: 2022 | D8: 7 | E8: 7th Match, Super Four | F8: 44807 | G8: Super Four | H8: Super Four | I8: Saturday | J8: Sharjah Cricket Stadium | K8: Sharjah | L8: 6 PM (GST), 8 PM (BST) | M8: T20I | N8: 58 | O8: 57 | P8: 65 | Q8: 20.12 | R8: 3.05 | S8: 36 / 34 deg C | T8: 0.54 | U8: Passing Clouds | V8: 10 | W8: North East | X8: A balanced-to-batting-friendly surface that favored teams chasing under the lights | Y8: Afghanistan | Z8: Sri Lanka | AA8: Sri Lanka | AB8: Bowl | AC8: 49 | AD8: 57 | AE8: 175 | AF8: 179 | AG8: Sri Lanka | AH8: Rahmanullah Gurbaz | AI8: 12 | AJ8: 5 | AK8: 4 Wickets | AL8: Ahsan Raza | AM8: Gazi Sohel | AN8: Anil Chaudhary | AO8: Asif Yaqoob | AP8: Andy Pycroft | AQ8: Original dataset (user-supplied) | AR8: =IF(AB8="Bat",AA8,IF(AA8=Y8,Z8,Y8)) -> Afghanistan | AS8: =IF(AR8=Y8,Z8,Y8) -> Sri Lanka | AT8: =IF(AR8=Y8,AE8,AF8) -> 175 | AU8: =IF(AR8=Y8,AF8,AE8) -> 179 | AV8: =IF(AG8=Y8,Z8,Y8) -> Afghanistan | AW8: =IF(AE8=AF8,"Tie (Super Over)","Normal") -> Normal | AX8: =IF(AW8<>"Normal","Super Over",IF(AG8=AR8,"Batting First","Chasing")) -> Chasing | AY8: =IF(AA8=AG8,"Yes","No") -> Yes | AZ8: =IF(ISNUMBER(SEARCH("Wicket",AK8)),"Wickets",IF(ISNUMBER(SEARCH("Run",AK8)),"Runs","Super Over")) -> Wickets | BA8: =IF(AZ8="Super Over","",VALUE(LEFT(AK8,FIND(" ",AK8)-1))) -> 4 | BB8: =AE8+AF8 -> 354 | BC8: =ABS(AE8-AF8) -> 4 | BD8: =AC8+AD8 -> 106 | BE8: =AI8+AJ8 -> 17 | BF8: =B8&"|"&H8 -> Asia Cup 2022|Super Four
A9: AC2022-08 | B9: Asia Cup 2022 | C9: 2022 | D9: 8 | E9: 8th Match, Super Four | F9: 44808 | G9: Super Four | H9: Super Four | I9: Sunday | J9: Dubai International Cricket Stadium | K9: Dubai | L9: 6 PM (GST), 8 PM (BST) | M9: T20I | N9: 65 | O9: 80 | P9: 75 | Q9: 20.12 | R9: 3.05 | S9: 35 / 33 deg C | T9: 0.58 | U9: Clear | V9: 11 | W9: North North West | X9: A pitch with steep bounce | Y9: India | Z9: Pakistan | AA9: India | AB9: Bat | AC9: 62 | AD9: 44 | AE9: 181 | AF9: 182 | AG9: Pakistan | AH9: Mohammad Nawaz | AI9: 14 | AJ9: 8 | AK9: 5 Wickets | AL9: Masudur Rahman | AM9: Raveendra Wimalasiri | AN9: Raveendra Wimalasiri | AO9: Ahmad Shah Pakteen | AP9: Andy Pycroft | AQ9: Original dataset (user-supplied) | AR9: =IF(AB9="Bat",AA9,IF(AA9=Y9,Z9,Y9)) -> India | AS9: =IF(AR9=Y9,Z9,Y9) -> Pakistan | AT9: =IF(AR9=Y9,AE9,AF9) -> 181 | AU9: =IF(AR9=Y9,AF9,AE9) -> 182 | AV9: =IF(AG9=Y9,Z9,Y9) -> India | AW9: =IF(AE9=AF9,"Tie (Super Over)","Normal") -> Normal | AX9: =IF(AW9<>"Normal","Super Over",IF(AG9=AR9,"Batting First","Chasing")) -> Chasing | AY9: =IF(AA9=AG9,"Yes","No") -> No | AZ9: =IF(ISNUMBER(SEARCH("Wicket",AK9)),"Wickets",IF(ISNUMBER(SEARCH("Run",AK9)),"Runs","Super Over")) -> Wickets | BA9: =IF(AZ9="Super Over","",VALUE(LEFT(AK9,FIND(" ",AK9)-1))) -> 5 | BB9: =AE9+AF9 -> 363 | BC9: =ABS(AE9-AF9) -> 1 | BD9: =AC9+AD9 -> 106 | BE9: =AI9+AJ9 -> 22 | BF9: =B9&"|"&H9 -> Asia Cup 2022|Super Four
A10: AC2022-09 | B10: Asia Cup 2022 | C10: 2022 | D10: 9 | E10: 9th Match, Super Four | F10: 44810 | G10: Super Four | H10: Super Four | I10: Tuesday | J10: Dubai International Cricket Stadium | K10: Dubai | L10: 6 PM (GST), 8 PM (BST) | M10: T20I | N10: 65 | O10: 80 | P10: 75 | Q10: 20.12 | R10: 3.05 | S10: 36 / 35 deg C | T10: 0.42 | U10: Passing Clouds | V10: 12 | W10: North North West | X10: The track offered a balanced contest for both batters and bowlers rather than playing as a pure batting paradise. | Y10: India | Z10: Sri Lanka | AA10: Sri Lanka | AB10: Bowl | AC10: 44 | AD10: 57 | AE10: 173 | AF10: 174 | AG10: Sri Lanka | AH10: Dasun Shanaka | AI10: 8 | AJ10: 6 | AK10: 6 Wickets | AL10: Ahsan Raza | AM10: Bismillah Jan Shinwari | AN10: Ahmad Shah Pakteen | AO10: Asif Yaqoob | AP10: Andy Pycroft | AQ10: Original dataset (user-supplied) | AR10: =IF(AB10="Bat",AA10,IF(AA10=Y10,Z10,Y10)) -> India | AS10: =IF(AR10=Y10,Z10,Y10) -> Sri Lanka | AT10: =IF(AR10=Y10,AE10,AF10) -> 173 | AU10: =IF(AR10=Y10,AF10,AE10) -> 174 | AV10: =IF(AG10=Y10,Z10,Y10) -> India | AW10: =IF(AE10=AF10,"Tie (Super Over)","Normal") -> Normal | AX10: =IF(AW10<>"Normal","Super Over",IF(AG10=AR10,"Batting First","Chasing")) -> Chasing | AY10: =IF(AA10=AG10,"Yes","No") -> Yes | AZ10: =IF(ISNUMBER(SEARCH("Wicket",AK10)),"Wickets",IF(ISNUMBER(SEARCH("Run",AK10)),"Runs","Super Over")) -> Wickets | BA10: =IF(AZ10="Super Over","",VALUE(LEFT(AK10,FIND(" ",AK10)-1))) -> 6 | BB10: =AE10+AF10 -> 347 | BC10: =ABS(AE10-AF10) -> 1 | BD10: =AC10+AD10 -> 101 | BE10: =AI10+AJ10 -> 14 | BF10: =B10&"|"&H10 -> Asia Cup 2022|Super Four
A11: AC2022-10 | B11: Asia Cup 2022 | C11: 2022 | D11: 10 | E11: 10th Match, Super Four | F11: 44811 | G11: Super Four | H11: Super Four | I11: Wednesday | J11: Sharjah Cricket Stadium | K11: Sharjah | L11: 6 PM (GST), 8 PM (BST) | M11: T20I | N11: 58 | O11: 57 | P11: 65 | Q11: 20.12 | R11: 3.05 | S11: 36 / 33 deg C | T11: 0.48 | U11: Clear | V11: 14 | W11: North North East | X11: Low bounce and slow pace, making it challenging for fluent stroke-play. | Y11: Afghanistan | Z11: Pakistan | AA11: Pakistan | AB11: Bowl | AC11: 48 | AD11: 35 | AE11: 129 | AF11: 131 | AG11: Pakistan | AH11: Shadab Khan | AI11: 3 | AJ11: 5 | AK11: 1 Wicket | AL11: Anil Chaudhary | AM11: Jayaraman Madanagopal | AN11: Gazi Sohel | AO11: Raveendra Wimalasiri | AP11: Andy Pycroft | AQ11: Original dataset (user-supplied) | AR11: =IF(AB11="Bat",AA11,IF(AA11=Y11,Z11,Y11)) -> Afghanistan | AS11: =IF(AR11=Y11,Z11,Y11) -> Pakistan | AT11: =IF(AR11=Y11,AE11,AF11) -> 129 | AU11: =IF(AR11=Y11,AF11,AE11) -> 131 | AV11: =IF(AG11=Y11,Z11,Y11) -> Afghanistan | AW11: =IF(AE11=AF11,"Tie (Super Over)","Normal") -> Normal | AX11: =IF(AW11<>"Normal","Super Over",IF(AG11=AR11,"Batting First","Chasing")) -> Chasing | AY11: =IF(AA11=AG11,"Yes","No") -> Yes | AZ11: =IF(ISNUMBER(SEARCH("Wicket",AK11)),"Wickets",IF(ISNUMBER(SEARCH("Run",AK11)),"Runs","Super Over")) -> Wickets | BA11: =IF(AZ11="Super Over","",VALUE(LEFT(AK11,FIND(" ",AK11)-1))) -> 1 | BB11: =AE11+AF11 -> 260 | BC11: =ABS(AE11-AF11) -> 2 | BD11: =AC11+AD11 -> 83 | BE11: =AI11+AJ11 -> 8 | BF11: =B11&"|"&H11 -> Asia Cup 2022|Super Four
A12: AC2022-11 | B12: Asia Cup 2022 | C12: 2022 | D12: 11 | E12: 11th Match, Super Four | F12: 44812 | G12: Super Four | H12: Super Four | I12: Thursday | J12: Dubai International Cricket Stadium | K12: Dubai | L12: 6 PM (GST), 8 PM (BST) | M12: T20I | N12: 65 | O12: 80 | P12: 75 | Q12: 20.12 | R12: 3.05 | S12: 35 / 34 deg C | T12: 0.52 | U12: Passing Clouds | V12: 13 | W12: East | X12: Unexpected and significant swing with the new white ball, particularly during the initial overs | Y12: India | Z12: Afghanistan | AA12: Afghanistan | AB12: Bowl | AC12: 52 | AD12: 21 | AE12: 212 | AF12: 111 | AG12: India | AH12: Virat Kohli | AI12: 2 | AJ12: 3 | AK12: 101 Runs | AL12: Asif Yaqoob | AM12: Ruchira Palliyaguruge | AN12: Raveendra Wimalasiri | AO12: Gazi Sohel | AP12: Andy Pycroft | AQ12: Original dataset (user-supplied) | AR12: =IF(AB12="Bat",AA12,IF(AA12=Y12,Z12,Y12)) -> India | AS12: =IF(AR12=Y12,Z12,Y12) -> Afghanistan | AT12: =IF(AR12=Y12,AE12,AF12) -> 212 | AU12: =IF(AR12=Y12,AF12,AE12) -> 111 | AV12: =IF(AG12=Y12,Z12,Y12) -> Afghanistan | AW12: =IF(AE12=AF12,"Tie (Super Over)","Normal") -> Normal | AX12: =IF(AW12<>"Normal","Super Over",IF(AG12=AR12,"Batting First","Chasing")) -> Batting First | AY12: =IF(AA12=AG12,"Yes","No") -> No | AZ12: =IF(ISNUMBER(SEARCH("Wicket",AK12)),"Wickets",IF(ISNUMBER(SEARCH("Run",AK12)),"Runs","Super Over")) -> Runs | BA12: =IF(AZ12="Super Over","",VALUE(LEFT(AK12,FIND(" ",AK12)-1))) -> 101 | BB12: =AE12+AF12 -> 323 | BC12: =ABS(AE12-AF12) -> 101 | BD12: =AC12+AD12 -> 73 | BE12: =AI12+AJ12 -> 5 | BF12: =B12&"|"&H12 -> Asia Cup 2022|Super Four
A13: AC2022-12 | B13: Asia Cup 2022 | C13: 2022 | D13: 12 | E13: 12th Match, Super Four | F13: 44813 | G13: Super Four | H13: Super Four | I13: Friday | J13: Dubai International Cricket Stadium | K13: Dubai | L13: 6 PM (GST), 8 PM (BST) | M13: T20I | N13: 65 | O13: 80 | P13: 75 | Q13: 20.12 | R13: 3.05 | S13: 34 / 33 deg C | T13: 0.56 | U13: Passing Clouds | V13: 11 | W13: North North West | X13: The pitch offered decent turn and grip for quality spinners | Y13: Pakistan | Z13: Sri Lanka | AA13: Sri Lanka | AB13: Bowl | AC13: 49 | AD13: 37 | AE13: 121 | AF13: 124 | AG13: Sri Lanka | AH13: Wanindu Hasaranga | AI13: 17 | AJ13: 5 | AK13: 5 Wickets | AL13: Ahmad Shah Pakteen | AM13: Anil Chaudhary | AN13: Masudur Rahman | AO13: Bismillah Jan Shinwari | AP13: Andy Pycroft | AQ13: Original dataset (user-supplied) | AR13: =IF(AB13="Bat",AA13,IF(AA13=Y13,Z13,Y13)) -> Pakistan | AS13: =IF(AR13=Y13,Z13,Y13) -> Sri Lanka | AT13: =IF(AR13=Y13,AE13,AF13) -> 121 | AU13: =IF(AR13=Y13,AF13,AE13) -> 124 | AV13: =IF(AG13=Y13,Z13,Y13) -> Pakistan | AW13: =IF(AE13=AF13,"Tie (Super Over)","Normal") -> Normal | AX13: =IF(AW13<>"Normal","Super Over",IF(AG13=AR13,"Batting First","Chasing")) -> Chasing | AY13: =IF(AA13=AG13,"Yes","No") -> Yes | AZ13: =IF(ISNUMBER(SEARCH("Wicket",AK13)),"Wickets",IF(ISNUMBER(SEARCH("Run",AK13)),"Runs","Super Over")) -> Wickets | BA13: =IF(AZ13="Super Over","",VALUE(LEFT(AK13,FIND(" ",AK13)-1))) -> 5 | BB13: =AE13+AF13 -> 245 | BC13: =ABS(AE13-AF13) -> 3 | BD13: =AC13+AD13 -> 86 | BE13: =AI13+AJ13 -> 22 | BF13: =B13&"|"&H13 -> Asia Cup 2022|Super Four
A14: AC2022-13 | B14: Asia Cup 2022 | C14: 2022 | D14: 13 | E14: Final | F14: 44815 | G14: Final | H14: Final | I14: Sunday | J14: Dubai International Cricket Stadium | K14: Dubai | L14: 6 PM (GST), 8 PM (BST) | M14: T20I | N14: 65 | O14: 80 | P14: 75 | Q14: 20.12 | R14: 3.05 | S14: 35 / 33 deg C | T14: 0.6 | U14: Clear | V14: 12 | W14: North North West | X14: Favored the chasing side heavily due to the dew factor in the second innings | Y14: Sri Lanka | Z14: Pakistan | AA14: Pakistan | AB14: Bowl | AC14: 42 | AD14: 37 | AE14: 170 | AF14: 147 | AG14: Sri Lanka | AH14: Bhanuka Rajapaksa | AI14: 10 | AJ14: 14 | AK14: 23 Runs | AL14: Anil Chaudhary | AM14: Masudur Rahman | AN14: Bismillah Jan Shinwari | AO14: Jayaraman Madanagopal | AP14: Andy Pycroft | AQ14: Original dataset (user-supplied) | AR14: =IF(AB14="Bat",AA14,IF(AA14=Y14,Z14,Y14)) -> Sri Lanka | AS14: =IF(AR14=Y14,Z14,Y14) -> Pakistan | AT14: =IF(AR14=Y14,AE14,AF14) -> 170 | AU14: =IF(AR14=Y14,AF14,AE14) -> 147 | AV14: =IF(AG14=Y14,Z14,Y14) -> Pakistan | AW14: =IF(AE14=AF14,"Tie (Super Over)","Normal") -> Normal | AX14: =IF(AW14<>"Normal","Super Over",IF(AG14=AR14,"Batting First","Chasing")) -> Batting First | AY14: =IF(AA14=AG14,"Yes","No") -> No | AZ14: =IF(ISNUMBER(SEARCH("Wicket",AK14)),"Wickets",IF(ISNUMBER(SEARCH("Run",AK14)),"Runs","Super Over")) -> Runs | BA14: =IF(AZ14="Super Over","",VALUE(LEFT(AK14,FIND(" ",AK14)-1))) -> 23 | BB14: =AE14+AF14 -> 317 | BC14: =ABS(AE14-AF14) -> 23 | BD14: =AC14+AD14 -> 79 | BE14: =AI14+AJ14 -> 24 | BF14: =B14&"|"&H14 -> Asia Cup 2022|Final
A15: AC2025-01 | B15: Asia Cup 2025 | C15: 2025 | D15: 1 | E15: 1st Match, Group B | F15: 45909 | G15: B | H15: Group Stage | I15: Tuesday | J15: Sheikh Zayed Stadium | K15: Abu Dhabi | L15: 6:30 PM (GST), 8:30 PM (BST) | M15: T20I | Q15: 20.12 | R15: 3.05 | S15: ~36 deg C | U15: Clear | X15: Usually batter-friendly, especially early on; true, even bounce that rewards stroke play. | Y15: Afghanistan | Z15: Hong Kong | AA15: Afghanistan | AB15: Bat | AC15: 41 | AD15: 23 | AE15: 188 | AF15: 94 | AG15: Afghanistan | AH15: Azmatullah Omarzai | AI15: 10 | AJ15: 10 | AK15: 94 Runs | AL15: Asif Yaqoob | AM15: Virender Sharma | AN15: Faisal Afridi | AP15: Richie Richardson | AQ15: Condition: Wisden match page. Temp: WION pre-match forecast. Pitch: WION / Cricket Times previews. | AR15: =IF(AB15="Bat",AA15,IF(AA15=Y15,Z15,Y15)) -> Afghanistan | AS15: =IF(AR15=Y15,Z15,Y15) -> Hong Kong | AT15: =IF(AR15=Y15,AE15,AF15) -> 188 | AU15: =IF(AR15=Y15,AF15,AE15) -> 94 | AV15: =IF(AG15=Y15,Z15,Y15) -> Hong Kong | AW15: =IF(AE15=AF15,"Tie (Super Over)","Normal") -> Normal | AX15: =IF(AW15<>"Normal","Super Over",IF(AG15=AR15,"Batting First","Chasing")) -> Batting First | AY15: =IF(AA15=AG15,"Yes","No") -> Yes | AZ15: =IF(ISNUMBER(SEARCH("Wicket",AK15)),"Wickets",IF(ISNUMBER(SEARCH("Run",AK15)),"Runs","Super Over")) -> Runs | BA15: =IF(AZ15="Super Over","",VALUE(LEFT(AK15,FIND(" ",AK15)-1))) -> 94 | BB15: =AE15+AF15 -> 282 | BC15: =ABS(AE15-AF15) -> 94 | BD15: =AC15+AD15 -> 64 | BE15: =AI15+AJ15 -> 20 | BF15: =B15&"|"&H15 -> Asia Cup 2025|Group Stage
A16: AC2025-02 | B16: Asia Cup 2025 | C16: 2025 | D16: 2 | E16: 2nd Match, Group A | F16: 45910 | G16: A | H16: Group Stage | I16: Wednesday | J16: Dubai International Cricket Stadium | K16: Dubai | L16: 6:30 PM (GST), 8:30 PM (BST) | M16: T20I | N16: 65 | O16: 80 | P16: 75 | Q16: 20.12 | R16: 3.05 | S16: ~35-36 deg C | U16: Clear / Partly Cloudy (forecast) | X16: Newly laid pitch with some cracks on a calmer day for heat; pace bowlers usually get early movement and bounce under lights. | Y16: United Arab Emirates | Z16: India | AA16: India | AB16: Bowl | AC16: 41 | AD16: 60 | AE16: 57 | AF16: 60 | AG16: India | AH16: Kuldeep Yadav | AI16: 2 | AJ16: 3 | AK16: 9 Wickets | AL16: Gazi Sohel | AM16: Izatullah Safi | AN16: Ruchira Palliyaguruge | AP16: Andy Pycroft | AQ16: Temp/condition: WION and Sportskeeda forecasts (they differ on humidity, 51% vs 65%, so humidity left blank). Pitch: Business Standard pitch report (Arnold/Manjrekar). | AR16: =IF(AB16="Bat",AA16,IF(AA16=Y16,Z16,Y16)) -> United Arab Emirates | AS16: =IF(AR16=Y16,Z16,Y16) -> India | AT16: =IF(AR16=Y16,AE16,AF16) -> 57 | AU16: =IF(AR16=Y16,AF16,AE16) -> 60 | AV16: =IF(AG16=Y16,Z16,Y16) -> United Arab Emirates | AW16: =IF(AE16=AF16,"Tie (Super Over)","Normal") -> Normal | AX16: =IF(AW16<>"Normal","Super Over",IF(AG16=AR16,"Batting First","Chasing")) -> Chasing | AY16: =IF(AA16=AG16,"Yes","No") -> Yes | AZ16: =IF(ISNUMBER(SEARCH("Wicket",AK16)),"Wickets",IF(ISNUMBER(SEARCH("Run",AK16)),"Runs","Super Over")) -> Wickets | BA16: =IF(AZ16="Super Over","",VALUE(LEFT(AK16,FIND(" ",AK16)-1))) -> 9 | BB16: =AE16+AF16 -> 117 | BC16: =ABS(AE16-AF16) -> 3 | BD16: =AC16+AD16 -> 101 | BE16: =AI16+AJ16 -> 5 | BF16: =B16&"|"&H16 -> Asia Cup 2025|Group Stage
A17: AC2025-03 | B17: Asia Cup 2025 | C17: 2025 | D17: 3 | E17: 3rd Match, Group B | F17: 45911 | G17: B | H17: Group Stage | I17: Thursday | J17: Sheikh Zayed Stadium | K17: Abu Dhabi | L17: 6:30 PM (GST), 8:30 PM (BST) | M17: T20I | Q17: 20.12 | R17: 3.05 | S17: ~36-40 deg C | U17: Clear (forecast) | X17: Dry surface with some cracks opening up but still run-friendly; shorter boundary on one side of the ground. | Y17: Hong Kong | Z17: Bangladesh | AA17: Bangladesh | AB17: Bowl | AC17: 34 | AD17: 51 | AE17: 143 | AF17: 144 | AG17: Bangladesh | AH17: Litton Das | AI17: 14 | AJ17: 17 | AK17: 7 Wickets | AL17: Raveendra Wimalasiri | AM17: Rohan Pandit | AN17: Asif Yaqoob | AP17: Richie Richardson | AQ17: Temp: WION forecast. Condition: Possible11 forecast. Pitch/boundary note: ESPN toss report. | AR17: =IF(AB17="Bat",AA17,IF(AA17=Y17,Z17,Y17)) -> Hong Kong | AS17: =IF(AR17=Y17,Z17,Y17) -> Bangladesh | AT17: =IF(AR17=Y17,AE17,AF17) -> 143 | AU17: =IF(AR17=Y17,AF17,AE17) -> 144 | AV17: =IF(AG17=Y17,Z17,Y17) -> Hong Kong | AW17: =IF(AE17=AF17,"Tie (Super Over)","Normal") -> Normal | AX17: =IF(AW17<>"Normal","Super Over",IF(AG17=AR17,"Batting First","Chasing")) -> Chasing | AY17: =IF(AA17=AG17,"Yes","No") -> Yes | AZ17: =IF(ISNUMBER(SEARCH("Wicket",AK17)),"Wickets",IF(ISNUMBER(SEARCH("Run",AK17)),"Runs","Super Over")) -> Wickets | BA17: =IF(AZ17="Super Over","",VALUE(LEFT(AK17,FIND(" ",AK17)-1))) -> 7 | BB17: =AE17+AF17 -> 287 | BC17: =ABS(AE17-AF17) -> 1 | BD17: =AC17+AD17 -> 85 | BE17: =AI17+AJ17 -> 31 | BF17: =B17&"|"&H17 -> Asia Cup 2025|Group Stage
A18: AC2025-04 | B18: Asia Cup 2025 | C18: 2025 | D18: 4 | E18: 4th Match, Group A | F18: 45912 | G18: A | H18: Group Stage | I18: Friday | J18: Dubai International Cricket Stadium | K18: Dubai | L18: 6:30 PM (GST), 8:30 PM (BST) | M18: T20I | N18: 65 | O18: 80 | P18: 75 | Q18: 20.12 | R18: 3.05 | U18: Clear (forecast) | X18: A little grass on the wicket; consistent bounce and carry, with pacers getting bounce and a hint of movement early before it flattens out. | Y18: Pakistan | Z18: Oman | AA18: Pakistan | AB18: Bat | AC18: 47 | AD18: 40 | AE18: 160 | AF18: 67 | AG18: Pakistan | AH18: Mohammad Haris | AI18: 4 | AJ18: 3 | AK18: 93 Runs | AL18: Masudur Rahman | AM18: Ahmad Shah Pakteen | AN18: Gazi Sohel | AP18: Andy Pycroft | AQ18: Condition: WION forecast. Pitch: Cricket Times and Dynamite News previews. | AR18: =IF(AB18="Bat",AA18,IF(AA18=Y18,Z18,Y18)) -> Pakistan | AS18: =IF(AR18=Y18,Z18,Y18) -> Oman | AT18: =IF(AR18=Y18,AE18,AF18) -> 160 | AU18: =IF(AR18=Y18,AF18,AE18) -> 67 | AV18: =IF(AG18=Y18,Z18,Y18) -> Oman | AW18: =IF(AE18=AF18,"Tie (Super Over)","Normal") -> Normal | AX18: =IF(AW18<>"Normal","Super Over",IF(AG18=AR18,"Batting First","Chasing")) -> Batting First | AY18: =IF(AA18=AG18,"Yes","No") -> Yes | AZ18: =IF(ISNUMBER(SEARCH("Wicket",AK18)),"Wickets",IF(ISNUMBER(SEARCH("Run",AK18)),"Runs","Super Over")) -> Runs | BA18: =IF(AZ18="Super Over","",VALUE(LEFT(AK18,FIND(" ",AK18)-1))) -> 93 | BB18: =AE18+AF18 -> 227 | BC18: =ABS(AE18-AF18) -> 93 | BD18: =AC18+AD18 -> 87 | BE18: =AI18+AJ18 -> 7 | BF18: =B18&"|"&H18 -> Asia Cup 2025|Group Stage
A19: AC2025-05 | B19: Asia Cup 2025 | C19: 2025 | D19: 5 | E19: 5th Match, Group B | F19: 45913 | G19: B | H19: Group Stage | I19: Saturday | J19: Sheikh Zayed Stadium | K19: Abu Dhabi | L19: 6:30 PM (GST), 8:30 PM (BST) | M19: T20I | Q19: 20.12 | R19: 3.05 | X19: Balanced contest; offers just enough grip for spinners in the middle overs. | Y19: Bangladesh | Z19: Sri Lanka | AA19: Sri Lanka | AB19: Bowl | AC19: 30 | AD19: 55 | AE19: 139 | AF19: 140 | AG19: Sri Lanka | AH19: Kamil Mishara | AI19: 11 | AJ19: 21 | AK19: 6 Wickets | AL19: Faisal Afridi | AM19: Rohan Pandit | AN19: Virender Sharma | AP19: Richie Richardson | AQ19: Pitch: Cricket Times preview. No weather data found for this match. | AR19: =IF(AB19="Bat",AA19,IF(AA19=Y19,Z19,Y19)) -> Bangladesh | AS19: =IF(AR19=Y19,Z19,Y19) -> Sri Lanka | AT19: =IF(AR19=Y19,AE19,AF19) -> 139 | AU19: =IF(AR19=Y19,AF19,AE19) -> 140 | AV19: =IF(AG19=Y19,Z19,Y19) -> Bangladesh | AW19: =IF(AE19=AF19,"Tie (Super Over)","Normal") -> Normal | AX19: =IF(AW19<>"Normal","Super Over",IF(AG19=AR19,"Batting First","Chasing")) -> Chasing | AY19: =IF(AA19=AG19,"Yes","No") -> Yes | AZ19: =IF(ISNUMBER(SEARCH("Wicket",AK19)),"Wickets",IF(ISNUMBER(SEARCH("Run",AK19)),"Runs","Super Over")) -> Wickets | BA19: =IF(AZ19="Super Over","",VALUE(LEFT(AK19,FIND(" ",AK19)-1))) -> 6 | BB19: =AE19+AF19 -> 279 | BC19: =ABS(AE19-AF19) -> 1 | BD19: =AC19+AD19 -> 85 | BE19: =AI19+AJ19 -> 32 | BF19: =B19&"|"&H19 -> Asia Cup 2025|Group Stage
A20: AC2025-06 | B20: Asia Cup 2025 | C20: 2025 | D20: 6 | E20: 6th Match, Group A | F20: 45914 | G20: A | H20: Group Stage | I20: Sunday | J20: Dubai International Cricket Stadium | K20: Dubai | L20: 6:30 PM (GST), 8:30 PM (BST) | M20: T20I | N20: 65 | O20: 80 | P20: 75 | Q20: 20.12 | R20: 3.05 | S20: 40 / 30 deg C | T20: 0.38 | U20: Clear | V20: 33 | X20: Fresh surface helping fast bowlers early, with seam movement for the right lengths; easier for batters in the middle overs. Described as a fair contest with help for seamers and spinners. | Y20: Pakistan | Z20: India | AA20: Pakistan | AB20: Bat | AC20: 42 | AD20: 61 | AE20: 127 | AF20: 131 | AG20: India | AH20: Kuldeep Yadav | AI20: 5 | AJ20: 2 | AK20: 7 Wickets | AL20: Masudur Rahman | AM20: Ruchira Palliyaguruge | AN20: Ahmad Shah Pakteen | AP20: Andy Pycroft | AQ20: Condition: Wisden. Temp (day high / night), humidity: Gulf News forecast. Wind (forecast maximum 33 km/h): Free Press Journal. Pitch: Free Press Journal, Gulf News. | AR20: =IF(AB20="Bat",AA20,IF(AA20=Y20,Z20,Y20)) -> Pakistan | AS20: =IF(AR20=Y20,Z20,Y20) -> India | AT20: =IF(AR20=Y20,AE20,AF20) -> 127 | AU20: =IF(AR20=Y20,AF20,AE20) -> 131 | AV20: =IF(AG20=Y20,Z20,Y20) -> Pakistan | AW20: =IF(AE20=AF20,"Tie (Super Over)","Normal") -> Normal | AX20: =IF(AW20<>"Normal","Super Over",IF(AG20=AR20,"Batting First","Chasing")) -> Chasing | AY20: =IF(AA20=AG20,"Yes","No") -> No | AZ20: =IF(ISNUMBER(SEARCH("Wicket",AK20)),"Wickets",IF(ISNUMBER(SEARCH("Run",AK20)),"Runs","Super Over")) -> Wickets | BA20: =IF(AZ20="Super Over","",VALUE(LEFT(AK20,FIND(" ",AK20)-1))) -> 7 | BB20: =AE20+AF20 -> 258 | BC20: =ABS(AE20-AF20) -> 4 | BD20: =AC20+AD20 -> 103 | BE20: =AI20+AJ20 -> 7 | BF20: =B20&"|"&H20 -> Asia Cup 2025|Group Stage
A21: AC2025-07 | B21: Asia Cup 2025 | C21: 2025 | D21: 7 | E21: 7th Match, Group A | F21: 45915 | G21: A | H21: Group Stage | I21: Monday | J21: Sheikh Zayed Stadium | K21: Abu Dhabi | L21: 4 PM (GST), 6 PM (BST) | M21: T20I | Q21: 20.12 | R21: 3.05 | U21: Clear | X21: Slow and low with plenty for spinners; player of the match said the ball was not coming onto the bat in the 4 PM start. | Y21: United Arab Emirates | Z21: Oman | AA21: Oman | AB21: Bowl | AC21: 50 | AD21: 41 | AE21: 172 | AF21: 130 | AG21: United Arab Emirates | AH21: Alishan Sharafu | AI21: 9 | AJ21: 16 | AK21: 42 Runs | AL21: Virender Sharma | AM21: Asif Yaqoob | AN21: Raveendra Wimalasiri | AP21: Richie Richardson | AQ21: Condition: Wisden. Pitch: Business Standard; ESPNcricinfo post-match comments (Sharafu). | AR21: =IF(AB21="Bat",AA21,IF(AA21=Y21,Z21,Y21)) -> United Arab Emirates | AS21: =IF(AR21=Y21,Z21,Y21) -> Oman | AT21: =IF(AR21=Y21,AE21,AF21) -> 172 | AU21: =IF(AR21=Y21,AF21,AE21) -> 130 | AV21: =IF(AG21=Y21,Z21,Y21) -> Oman | AW21: =IF(AE21=AF21,"Tie (Super Over)","Normal") -> Normal | AX21: =IF(AW21<>"Normal","Super Over",IF(AG21=AR21,"Batting First","Chasing")) -> Batting First | AY21: =IF(AA21=AG21,"Yes","No") -> No | AZ21: =IF(ISNUMBER(SEARCH("Wicket",AK21)),"Wickets",IF(ISNUMBER(SEARCH("Run",AK21)),"Runs","Super Over")) -> Runs | BA21: =IF(AZ21="Super Over","",VALUE(LEFT(AK21,FIND(" ",AK21)-1))) -> 42 | BB21: =AE21+AF21 -> 302 | BC21: =ABS(AE21-AF21) -> 42 | BD21: =AC21+AD21 -> 91 | BE21: =AI21+AJ21 -> 25 | BF21: =B21&"|"&H21 -> Asia Cup 2025|Group Stage
A22: AC2025-08 | B22: Asia Cup 2025 | C22: 2025 | D22: 8 | E22: 8th Match, Group B | F22: 45915 | G22: B | H22: Group Stage | I22: Monday | J22: Dubai International Cricket Stadium | K22: Dubai | L22: 6:30 PM (GST), 8:30 PM (BST) | M22: T20I | N22: 65 | O22: 80 | P22: 75 | Q22: 20.12 | R22: 3.05 | U22: Clear | X22: Called a good Dubai deck by the Sri Lanka captain; tends to slow down as the match goes on, giving spinners a bigger role. | Y22: Hong Kong | Z22: Sri Lanka | AA22: Sri Lanka | AB22: Bowl | AC22: 42 | AD22: 35 | AE22: 149 | AF22: 153 | AG22: Sri Lanka | AH22: Pathum Nissanka | AI22: 13 | AJ22: 2 | AK22: 4 Wickets | AL22: Gazi Sohel | AM22: Izatullah Safi | AN22: Masudur Rahman | AP22: Andy Pycroft | AQ22: Condition: Wisden. Pitch: Ada Derana toss report, Cricket Times preview. | AR22: =IF(AB22="Bat",AA22,IF(AA22=Y22,Z22,Y22)) -> Hong Kong | AS22: =IF(AR22=Y22,Z22,Y22) -> Sri Lanka | AT22: =IF(AR22=Y22,AE22,AF22) -> 149 | AU22: =IF(AR22=Y22,AF22,AE22) -> 153 | AV22: =IF(AG22=Y22,Z22,Y22) -> Hong Kong | AW22: =IF(AE22=AF22,"Tie (Super Over)","Normal") -> Normal | AX22: =IF(AW22<>"Normal","Super Over",IF(AG22=AR22,"Batting First","Chasing")) -> Chasing | AY22: =IF(AA22=AG22,"Yes","No") -> Yes | AZ22: =IF(ISNUMBER(SEARCH("Wicket",AK22)),"Wickets",IF(ISNUMBER(SEARCH("Run",AK22)),"Runs","Super Over")) -> Wickets | BA22: =IF(AZ22="Super Over","",VALUE(LEFT(AK22,FIND(" ",AK22)-1))) -> 4 | BB22: =AE22+AF22 -> 302 | BC22: =ABS(AE22-AF22) -> 4 | BD22: =AC22+AD22 -> 77 | BE22: =AI22+AJ22 -> 15 | BF22: =B22&"|"&H22 -> Asia Cup 2025|Group Stage
A23: AC2025-09 | B23: Asia Cup 2025 | C23: 2025 | D23: 9 | E23: 9th Match, Group B | F23: 45916 | G23: B | H23: Group Stage | I23: Tuesday | J23: Sheikh Zayed Stadium | K23: Abu Dhabi | L23: 6:30 PM (GST), 8:30 PM (BST) | M23: T20I | Q23: 20.12 | R23: 3.05 | U23: Clear | X23: Has helped teams batting first; slows as the game progresses so bowlers dominate the second half under lights. Dew was not an issue because of the heat. | Y23: Bangladesh | Z23: Afghanistan | AA23: Bangladesh | AB23: Bat | AC23: 59 | AD23: 27 | AE23: 154 | AF23: 146 | AG23: Bangladesh | AH23: Nasum Ahmed | AI23: 2 | AJ23: 3 | AK23: 8 Runs | AL23: Faisal Afridi | AM23: Raveendra Wimalasiri | AN23: Rohan Pandit | AP23: Richie Richardson | AQ23: Condition: Wisden. Pitch: CricTracker preview. | AR23: =IF(AB23="Bat",AA23,IF(AA23=Y23,Z23,Y23)) -> Bangladesh | AS23: =IF(AR23=Y23,Z23,Y23) -> Afghanistan | AT23: =IF(AR23=Y23,AE23,AF23) -> 154 | AU23: =IF(AR23=Y23,AF23,AE23) -> 146 | AV23: =IF(AG23=Y23,Z23,Y23) -> Afghanistan | AW23: =IF(AE23=AF23,"Tie (Super Over)","Normal") -> Normal | AX23: =IF(AW23<>"Normal","Super Over",IF(AG23=AR23,"Batting First","Chasing")) -> Batting First | AY23: =IF(AA23=AG23,"Yes","No") -> Yes | AZ23: =IF(ISNUMBER(SEARCH("Wicket",AK23)),"Wickets",IF(ISNUMBER(SEARCH("Run",AK23)),"Runs","Super Over")) -> Runs | BA23: =IF(AZ23="Super Over","",VALUE(LEFT(AK23,FIND(" ",AK23)-1))) -> 8 | BB23: =AE23+AF23 -> 300 | BC23: =ABS(AE23-AF23) -> 8 | BD23: =AC23+AD23 -> 86 | BE23: =AI23+AJ23 -> 5 | BF23: =B23&"|"&H23 -> Asia Cup 2025|Group Stage
A24: AC2025-10 | B24: Asia Cup 2025 | C24: 2025 | D24: 10 | E24: 10th Match, Group A | F24: 45917 | G24: A | H24: Group Stage | I24: Wednesday | J24: Dubai International Cricket Stadium | K24: Dubai | L24: 6:30 PM (GST), 8:30 PM (BST) | M24: T20I | N24: 65 | O24: 80 | P24: 75 | Q24: 20.12 | R24: 3.05 | U24: Clear | X24: Balanced contest between bat and ball. | Y24: Pakistan | Z24: United Arab Emirates | AA24: United Arab Emirates | AB24: Bowl | AC24: 39 | AD24: 38 | AE24: 146 | AF24: 105 | AG24: Pakistan | AH24: Shaheen Afridi | AI24: 13 | AJ24: 11 | AK24: 41 Runs | AL24: Ahmad Shah Pakteen | AM24: Ruchira Palliyaguruge | AN24: Izatullah Safi | AP24: Andy Pycroft | AQ24: Condition: Wisden. Pitch: WION preview. | AR24: =IF(AB24="Bat",AA24,IF(AA24=Y24,Z24,Y24)) -> Pakistan | AS24: =IF(AR24=Y24,Z24,Y24) -> United Arab Emirates | AT24: =IF(AR24=Y24,AE24,AF24) -> 146 | AU24: =IF(AR24=Y24,AF24,AE24) -> 105 | AV24: =IF(AG24=Y24,Z24,Y24) -> United Arab Emirates | AW24: =IF(AE24=AF24,"Tie (Super Over)","Normal") -> Normal | AX24: =IF(AW24<>"Normal","Super Over",IF(AG24=AR24,"Batting First","Chasing")) -> Batting First | AY24: =IF(AA24=AG24,"Yes","No") -> No | AZ24: =IF(ISNUMBER(SEARCH("Wicket",AK24)),"Wickets",IF(ISNUMBER(SEARCH("Run",AK24)),"Runs","Super Over")) -> Runs | BA24: =IF(AZ24="Super Over","",VALUE(LEFT(AK24,FIND(" ",AK24)-1))) -> 41 | BB24: =AE24+AF24 -> 251 | BC24: =ABS(AE24-AF24) -> 41 | BD24: =AC24+AD24 -> 77 | BE24: =AI24+AJ24 -> 24 | BF24: =B24&"|"&H24 -> Asia Cup 2025|Group Stage
A25: AC2025-11 | B25: Asia Cup 2025 | C25: 2025 | D25: 11 | E25: 11th Match, Group B | F25: 45918 | G25: B | H25: Group Stage | I25: Thursday | J25: Sheikh Zayed Stadium | K25: Abu Dhabi | L25: 6:30 PM (GST), 8:30 PM (BST) | M25: T20I | Q25: 20.12 | R25: 3.05 | S25: ~38-40 deg C | T25: 0.39 | U25: Clear (forecast: dry) | X25: Balanced: batters have the better of it early, spinners later; some early movement for fast bowlers under lights. | Y25: Afghanistan | Z25: Sri Lanka | AA25: Afghanistan | AB25: Bat | AC25: 45 | AD25: 53 | AE25: 169 | AF25: 171 | AG25: Sri Lanka | AH25: Kusal Mendis | AI25: 7 | AJ25: 16 | AK25: 6 Wickets | AL25: Asif Yaqoob | AM25: Virender Sharma | AN25: Faisal Afridi | AP25: Richie Richardson | AQ25: Temp/condition: Outlook India forecast. Humidity: WION forecast. Pitch: Outlook India, WION, Sony LIV. | AR25: =IF(AB25="Bat",AA25,IF(AA25=Y25,Z25,Y25)) -> Afghanistan | AS25: =IF(AR25=Y25,Z25,Y25) -> Sri Lanka | AT25: =IF(AR25=Y25,AE25,AF25) -> 169 | AU25: =IF(AR25=Y25,AF25,AE25) -> 171 | AV25: =IF(AG25=Y25,Z25,Y25) -> Afghanistan | AW25: =IF(AE25=AF25,"Tie (Super Over)","Normal") -> Normal | AX25: =IF(AW25<>"Normal","Super Over",IF(AG25=AR25,"Batting First","Chasing")) -> Chasing | AY25: =IF(AA25=AG25,"Yes","No") -> No | AZ25: =IF(ISNUMBER(SEARCH("Wicket",AK25)),"Wickets",IF(ISNUMBER(SEARCH("Run",AK25)),"Runs","Super Over")) -> Wickets | BA25: =IF(AZ25="Super Over","",VALUE(LEFT(AK25,FIND(" ",AK25)-1))) -> 6 | BB25: =AE25+AF25 -> 340 | BC25: =ABS(AE25-AF25) -> 2 | BD25: =AC25+AD25 -> 98 | BE25: =AI25+AJ25 -> 23 | BF25: =B25&"|"&H25 -> Asia Cup 2025|Group Stage
A26: AC2025-12 | B26: Asia Cup 2025 | C26: 2025 | D26: 12 | E26: 12th Match, Group A | F26: 45919 | G26: A | H26: Group Stage | I26: Friday | J26: Sheikh Zayed Stadium | K26: Abu Dhabi | L26: 6:30 PM (GST), 8:30 PM (BST) | M26: T20I | Q26: 20.12 | R26: 3.05 | U26: Clear | X26: Balanced contest; runs tend to come faster in the first half of the match. | Y26: India | Z26: Oman | AA26: India | AB26: Bat | AC26: 60 | AD26: 44 | AE26: 188 | AF26: 167 | AG26: India | AH26: Sanju Samson | AI26: 13 | AJ26: 7 | AK26: 21 Runs | AL26: Raveendra Wimalasiri | AM26: Faisal Afridi | AN26: Asif Yaqoob | AP26: Richie Richardson | AQ26: Condition: Wisden. Pitch: CricTracker, WION previews. | AR26: =IF(AB26="Bat",AA26,IF(AA26=Y26,Z26,Y26)) -> India | AS26: =IF(AR26=Y26,Z26,Y26) -> Oman | AT26: =IF(AR26=Y26,AE26,AF26) -> 188 | AU26: =IF(AR26=Y26,AF26,AE26) -> 167 | AV26: =IF(AG26=Y26,Z26,Y26) -> Oman | AW26: =IF(AE26=AF26,"Tie (Super Over)","Normal") -> Normal | AX26: =IF(AW26<>"Normal","Super Over",IF(AG26=AR26,"Batting First","Chasing")) -> Batting First | AY26: =IF(AA26=AG26,"Yes","No") -> Yes | AZ26: =IF(ISNUMBER(SEARCH("Wicket",AK26)),"Wickets",IF(ISNUMBER(SEARCH("Run",AK26)),"Runs","Super Over")) -> Runs | BA26: =IF(AZ26="Super Over","",VALUE(LEFT(AK26,FIND(" ",AK26)-1))) -> 21 | BB26: =AE26+AF26 -> 355 | BC26: =ABS(AE26-AF26) -> 21 | BD26: =AC26+AD26 -> 104 | BE26: =AI26+AJ26 -> 20 | BF26: =B26&"|"&H26 -> Asia Cup 2025|Group Stage
A27: AC2025-13 | B27: Asia Cup 2025 | C27: 2025 | D27: 13 | E27: 13th Match, Super Four (B1 v B2) | F27: 45920 | G27: Super Four | H27: Super Four | I27: Saturday | J27: Dubai International Cricket Stadium | K27: Dubai | L27: 6:30 PM (GST), 8:30 PM (BST) | M27: T20I | N27: 65 | O27: 80 | P27: 75 | Q27: 20.12 | R27: 3.05 | U27: Clear | X27: Even bounce, with possible evening dew helping the chasing side. | Y27: Sri Lanka | Z27: Bangladesh | AA27: Bangladesh | AB27: Bowl | AC27: 53 | AD27: 59 | AE27: 168 | AF27: 169 | AG27: Bangladesh | AH27: Saif Hassan | AI27: 3 | AJ27: 3 | AK27: 4 Wickets | AL27: Asif Yaqoob | AM27: Rohan Pandit | AN27: Virender Sharma | AP27: Andy Pycroft | AQ27: Condition: Wisden. Pitch: Sony LIV preview. | AR27: =IF(AB27="Bat",AA27,IF(AA27=Y27,Z27,Y27)) -> Sri Lanka | AS27: =IF(AR27=Y27,Z27,Y27) -> Bangladesh | AT27: =IF(AR27=Y27,AE27,AF27) -> 168 | AU27: =IF(AR27=Y27,AF27,AE27) -> 169 | AV27: =IF(AG27=Y27,Z27,Y27) -> Sri Lanka | AW27: =IF(AE27=AF27,"Tie (Super Over)","Normal") -> Normal | AX27: =IF(AW27<>"Normal","Super Over",IF(AG27=AR27,"Batting First","Chasing")) -> Chasing | AY27: =IF(AA27=AG27,"Yes","No") -> Yes | AZ27: =IF(ISNUMBER(SEARCH("Wicket",AK27)),"Wickets",IF(ISNUMBER(SEARCH("Run",AK27)),"Runs","Super Over")) -> Wickets | BA27: =IF(AZ27="Super Over","",VALUE(LEFT(AK27,FIND(" ",AK27)-1))) -> 4 | BB27: =AE27+AF27 -> 337 | BC27: =ABS(AE27-AF27) -> 1 | BD27: =AC27+AD27 -> 112 | BE27: =AI27+AJ27 -> 6 | BF27: =B27&"|"&H27 -> Asia Cup 2025|Super Four
A28: AC2025-14 | B28: Asia Cup 2025 | C28: 2025 | D28: 14 | E28: 14th Match, Super Four (A1 v A2) | F28: 45921 | G28: Super Four | H28: Super Four | I28: Sunday | J28: Dubai International Cricket Stadium | K28: Dubai | L28: 6:30 PM (GST), 8:30 PM (BST) | M28: T20I | N28: 65 | O28: 80 | P28: 75 | Q28: 20.12 | R28: 3.05 | U28: Clear | X28: Venue-level note only (no match-specific report found): Dubai surface generally gives a balanced contest between bat and ball. | Y28: Pakistan | Z28: India | AA28: India | AB28: Bowl | AC28: 55 | AD28: 69 | AE28: 171 | AF28: 174 | AG28: India | AH28: Abhishek Sharma | AI28: 9 | AJ28: 3 | AK28: 6 Wickets | AL28: Gazi Sohel | AM28: Ahmad Shah Pakteen | AN28: Ruchira Palliyaguruge | AP28: Andy Pycroft | AQ28: Condition: Wisden. Pitch: WION venue description. | AR28: =IF(AB28="Bat",AA28,IF(AA28=Y28,Z28,Y28)) -> Pakistan | AS28: =IF(AR28=Y28,Z28,Y28) -> India | AT28: =IF(AR28=Y28,AE28,AF28) -> 171 | AU28: =IF(AR28=Y28,AF28,AE28) -> 174 | AV28: =IF(AG28=Y28,Z28,Y28) -> Pakistan | AW28: =IF(AE28=AF28,"Tie (Super Over)","Normal") -> Normal | AX28: =IF(AW28<>"Normal","Super Over",IF(AG28=AR28,"Batting First","Chasing")) -> Chasing | AY28: =IF(AA28=AG28,"Yes","No") -> Yes | AZ28: =IF(ISNUMBER(SEARCH("Wicket",AK28)),"Wickets",IF(ISNUMBER(SEARCH("Run",AK28)),"Runs","Super Over")) -> Wickets | BA28: =IF(AZ28="Super Over","",VALUE(LEFT(AK28,FIND(" ",AK28)-1))) -> 6 | BB28: =AE28+AF28 -> 345 | BC28: =ABS(AE28-AF28) -> 3 | BD28: =AC28+AD28 -> 124 | BE28: =AI28+AJ28 -> 12 | BF28: =B28&"|"&H28 -> Asia Cup 2025|Super Four
A29: AC2025-15 | B29: Asia Cup 2025 | C29: 2025 | D29: 15 | E29: 15th Match, Super Four (A2 v B1) | F29: 45923 | G29: Super Four | H29: Super Four | I29: Tuesday | J29: Sheikh Zayed Stadium | K29: Abu Dhabi | L29: 6:30 PM (GST), 8:30 PM (BST) | M29: T20I | Q29: 20.12 | R29: 3.05 | X29: Pakistan captain called it a good wicket and did not expect it to change during the game. | Y29: Sri Lanka | Z29: Pakistan | AA29: Pakistan | AB29: Bowl | AC29: 53 | AD29: 48 | AE29: 133 | AF29: 138 | AG29: Pakistan | AH29: Hussain Talat | AI29: 7 | AJ29: 7 | AK29: 5 Wickets | AL29: Izatullah Safi | AM29: Masudur Rahman | AN29: Gazi Sohel | AP29: Richie Richardson | AQ29: Pitch: IANS toss report. No weather data found for this match. | AR29: =IF(AB29="Bat",AA29,IF(AA29=Y29,Z29,Y29)) -> Sri Lanka | AS29: =IF(AR29=Y29,Z29,Y29) -> Pakistan | AT29: =IF(AR29=Y29,AE29,AF29) -> 133 | AU29: =IF(AR29=Y29,AF29,AE29) -> 138 | AV29: =IF(AG29=Y29,Z29,Y29) -> Sri Lanka | AW29: =IF(AE29=AF29,"Tie (Super Over)","Normal") -> Normal | AX29: =IF(AW29<>"Normal","Super Over",IF(AG29=AR29,"Batting First","Chasing")) -> Chasing | AY29: =IF(AA29=AG29,"Yes","No") -> Yes | AZ29: =IF(ISNUMBER(SEARCH("Wicket",AK29)),"Wickets",IF(ISNUMBER(SEARCH("Run",AK29)),"Runs","Super Over")) -> Wickets | BA29: =IF(AZ29="Super Over","",VALUE(LEFT(AK29,FIND(" ",AK29)-1))) -> 5 | BB29: =AE29+AF29 -> 271 | BC29: =ABS(AE29-AF29) -> 5 | BD29: =AC29+AD29 -> 101 | BE29: =AI29+AJ29 -> 14 | BF29: =B29&"|"&H29 -> Asia Cup 2025|Super Four
A30: AC2025-16 | B30: Asia Cup 2025 | C30: 2025 | D30: 16 | E30: 16th Match, Super Four (A1 v B2) | F30: 45924 | G30: Super Four | H30: Super Four | I30: Wednesday | J30: Dubai International Cricket Stadium | K30: Dubai | L30: 6:30 PM (GST), 8:30 PM (BST) | M30: T20I | N30: 65 | O30: 80 | P30: 75 | Q30: 20.12 | R30: 3.05 | U30: Clear | V30: 14 | X30: Generally dry; batter-friendly in recent matches, with chasing sides having the advantage (5 of 7 earlier Dubai games won by the chasing team). | Y30: India | Z30: Bangladesh | AA30: Bangladesh | AB30: Bowl | AC30: 72 | AD30: 44 | AE30: 168 | AF30: 127 | AG30: India | AH30: Abhishek Sharma | AI30: 4 | AJ30: 9 | AK30: 41 Runs | AL30: Ahmad Shah Pakteen | AM30: Ruchira Palliyaguruge | AN30: Raveendra Wimalasiri | AP30: Andy Pycroft | AQ30: Condition: Wisden. Wind (forecast): Sportskeeda. Pitch: Sportskeeda, CricTracker. | AR30: =IF(AB30="Bat",AA30,IF(AA30=Y30,Z30,Y30)) -> India | AS30: =IF(AR30=Y30,Z30,Y30) -> Bangladesh | AT30: =IF(AR30=Y30,AE30,AF30) -> 168 | AU30: =IF(AR30=Y30,AF30,AE30) -> 127 | AV30: =IF(AG30=Y30,Z30,Y30) -> Bangladesh | AW30: =IF(AE30=AF30,"Tie (Super Over)","Normal") -> Normal | AX30: =IF(AW30<>"Normal","Super Over",IF(AG30=AR30,"Batting First","Chasing")) -> Batting First | AY30: =IF(AA30=AG30,"Yes","No") -> No | AZ30: =IF(ISNUMBER(SEARCH("Wicket",AK30)),"Wickets",IF(ISNUMBER(SEARCH("Run",AK30)),"Runs","Super Over")) -> Runs | BA30: =IF(AZ30="Super Over","",VALUE(LEFT(AK30,FIND(" ",AK30)-1))) -> 41 | BB30: =AE30+AF30 -> 295 | BC30: =ABS(AE30-AF30) -> 41 | BD30: =AC30+AD30 -> 116 | BE30: =AI30+AJ30 -> 13 | BF30: =B30&"|"&H30 -> Asia Cup 2025|Super Four
A31: AC2025-17 | B31: Asia Cup 2025 | C31: 2025 | D31: 17 | E31: 17th Match, Super Four (A2 v B2) | F31: 45925 | G31: Super Four | H31: Super Four | I31: Thursday | J31: Dubai International Cricket Stadium | K31: Dubai | L31: 6:30 PM (GST), 8:30 PM (BST) | M31: T20I | N31: 65 | O31: 80 | P31: 75 | Q31: 20.12 | R31: 3.05 | U31: Clear | X31: Assists bowlers early, then slows down as the match progresses; most Dubai games this tournament were won by the chasing side. | Y31: Pakistan | Z31: Bangladesh | AA31: Bangladesh | AB31: Bowl | AC31: 27 | AD31: 36 | AE31: 135 | AF31: 124 | AG31: Pakistan | AH31: Shaheen Afridi | AI31: 4 | AJ31: 3 | AK31: 11 Runs | AL31: Ahmad Shah Pakteen | AM31: Raveendra Wimalasiri | AN31: Izatullah Safi | AP31: Andy Pycroft | AQ31: Condition: Wisden. Pitch: Cricket Times preview. | AR31: =IF(AB31="Bat",AA31,IF(AA31=Y31,Z31,Y31)) -> Pakistan | AS31: =IF(AR31=Y31,Z31,Y31) -> Bangladesh | AT31: =IF(AR31=Y31,AE31,AF31) -> 135 | AU31: =IF(AR31=Y31,AF31,AE31) -> 124 | AV31: =IF(AG31=Y31,Z31,Y31) -> Bangladesh | AW31: =IF(AE31=AF31,"Tie (Super Over)","Normal") -> Normal | AX31: =IF(AW31<>"Normal","Super Over",IF(AG31=AR31,"Batting First","Chasing")) -> Batting First | AY31: =IF(AA31=AG31,"Yes","No") -> No | AZ31: =IF(ISNUMBER(SEARCH("Wicket",AK31)),"Wickets",IF(ISNUMBER(SEARCH("Run",AK31)),"Runs","Super Over")) -> Runs | BA31: =IF(AZ31="Super Over","",VALUE(LEFT(AK31,FIND(" ",AK31)-1))) -> 11 | BB31: =AE31+AF31 -> 259 | BC31: =ABS(AE31-AF31) -> 11 | BD31: =AC31+AD31 -> 63 | BE31: =AI31+AJ31 -> 7 | BF31: =B31&"|"&H31 -> Asia Cup 2025|Super Four
A32: AC2025-18 | B32: Asia Cup 2025 | C32: 2025 | D32: 18 | E32: 18th Match, Super Four (A1 v B1) | F32: 45926 | G32: Super Four | H32: Super Four | I32: Friday | J32: Dubai International Cricket Stadium | K32: Dubai | L32: 6:30 PM (GST), 8:30 PM (BST) | M32: T20I | N32: 65 | O32: 80 | P32: 75 | Q32: 20.12 | R32: 3.05 | U32: Clear | X32: Batter-friendly in recent matches; a true surface with some early seam and later spin, with possible dew. | Y32: India | Z32: Sri Lanka | AA32: Sri Lanka | AB32: Bowl | AC32: 71 | AD32: 72 | AE32: 202 | AF32: 202 | AG32: India | AH32: Pathum Nissanka | AI32: 14 | AJ32: 5 | AK32: Super Over | AL32: Gazi Sohel | AM32: Izatullah Safi | AN32: Masudur Rahman | AP32: Richie Richardson | AQ32: Condition: Wisden. Pitch: CricTracker, Sony LIV previews. | AR32: =IF(AB32="Bat",AA32,IF(AA32=Y32,Z32,Y32)) -> India | AS32: =IF(AR32=Y32,Z32,Y32) -> Sri Lanka | AT32: =IF(AR32=Y32,AE32,AF32) -> 202 | AU32: =IF(AR32=Y32,AF32,AE32) -> 202 | AV32: =IF(AG32=Y32,Z32,Y32) -> Sri Lanka | AW32: =IF(AE32=AF32,"Tie (Super Over)","Normal") -> Tie (Super Over) | AX32: =IF(AW32<>"Normal","Super Over",IF(AG32=AR32,"Batting First","Chasing")) -> Super Over | AY32: =IF(AA32=AG32,"Yes","No") -> No | AZ32: =IF(ISNUMBER(SEARCH("Wicket",AK32)),"Wickets",IF(ISNUMBER(SEARCH("Run",AK32)),"Runs","Super Over")) -> Super Over | BA32: =IF(AZ32="Super Over","",VALUE(LEFT(AK32,FIND(" ",AK32)-1))) | BB32: =AE32+AF32 -> 404 | BC32: =ABS(AE32-AF32) -> 0 | BD32: =AC32+AD32 -> 143 | BE32: =AI32+AJ32 -> 19 | BF32: =B32&"|"&H32 -> Asia Cup 2025|Super Four
A33: AC2025-19 | B33: Asia Cup 2025 | C33: 2025 | D33: 19 | E33: Final | F33: 45928 | G33: Final | H33: Final | I33: Sunday | J33: Dubai International Cricket Stadium | K33: Dubai | L33: 6:30 PM (GST), 8:30 PM (BST) | M33: T20I | N33: 65 | O33: 80 | P33: 75 | Q33: 20.12 | R33: 3.05 | S33: 38-43 deg C (daytime) | U33: Clear | X33: Balanced; offers help to a variety of bowling styles. Dew was not a major factor in the tournament, and Dubai has traditionally favoured chasing sides. | Y33: Pakistan | Z33: India | AA33: India | AB33: Bowl | AC33: 45 | AD33: 36 | AE33: 146 | AF33: 150 | AG33: India | AH33: Tilak Varma | AI33: 7 | AJ33: 2 | AK33: 5 Wickets | AL33: Ahmad Shah Pakteen | AM33: Masudur Rahman | AN33: Raveendra Wimalasiri | AP33: Richie Richardson | AQ33: Condition: Wisden. Temp (daytime): Gulf News citing the National Center of Meteorology forecast. Pitch: Gulf News, Outlook India. | AR33: =IF(AB33="Bat",AA33,IF(AA33=Y33,Z33,Y33)) -> Pakistan | AS33: =IF(AR33=Y33,Z33,Y33) -> India | AT33: =IF(AR33=Y33,AE33,AF33) -> 146 | AU33: =IF(AR33=Y33,AF33,AE33) -> 150 | AV33: =IF(AG33=Y33,Z33,Y33) -> Pakistan | AW33: =IF(AE33=AF33,"Tie (Super Over)","Normal") -> Normal | AX33: =IF(AW33<>"Normal","Super Over",IF(AG33=AR33,"Batting First","Chasing")) -> Chasing | AY33: =IF(AA33=AG33,"Yes","No") -> Yes | AZ33: =IF(ISNUMBER(SEARCH("Wicket",AK33)),"Wickets",IF(ISNUMBER(SEARCH("Run",AK33)),"Runs","Super Over")) -> Wickets | BA33: =IF(AZ33="Super Over","",VALUE(LEFT(AK33,FIND(" ",AK33)-1))) -> 5 | BB33: =AE33+AF33 -> 296 | BC33: =ABS(AE33-AF33) -> 4 | BD33: =AC33+AD33 -> 81 | BE33: =AI33+AJ33 -> 9 | BF33: =B33&"|"&H33 -> Asia Cup 2025|Final

Sheet 2025 Scorecard Detail
A1: Match ID | B1: Match Label | C1: Date | D1: Team 1 | E1: Team 2 | F1: Team 1 Score Summary | G1: Team 1 Total Runs | H1: Team 1 Wickets Lost | I1: Team 1 Overs | J1: Team 1 Extras | K1: Team 1 Byes | L1: Team 1 Leg Byes | M1: Team 1 Wides | N1: Team 1 No Balls | O1: Team 1 Powerplay Runs | P1: Team 1 Powerplay Overs | Q1: Team 1 Fours | R1: Team 1 Sixes | S1: Team 1 Top Scorer | T1: Team 1 Top Wicket Taker | U1: Team 1 Coach | V1: Team 1 Playing XI | W1: Team 1 Batting Card (R/B/4s/6s) | X1: Team 1 Bowling Card (O-M-R-W) | Y1: Team 1 Fall of Wickets | Z1: Team 2 Score Summary | AA1: Team 2 Total Runs | AB1: Team 2 Wickets Lost | AC1: Team 2 Overs | AD1: Team 2 Extras | AE1: Team 2 Byes | AF1: Team 2 Leg Byes | AG1: Team 2 Wides | AH1: Team 2 No Balls | AI1: Team 2 Powerplay Runs | AJ1: Team 2 Powerplay Overs | AK1: Team 2 Fours | AL1: Team 2 Sixes | AM1: Team 2 Top Scorer | AN1: Team 2 Top Wicket Taker | AO1: Team 2 Coach | AP1: Team 2 Playing XI | AQ1: Team 2 Batting Card (R/B/4s/6s) | AR1: Team 2 Bowling Card (O-M-R-W) | AS1: Team 2 Fall of Wickets | AT1: Team 1 Boundary Runs | AU1: Team 2 Boundary Runs | AV1: Team 1 Boundary % | AW1: Team 2 Boundary % | AX1: Team 1 Run Rate | AY1: Team 2 Run Rate | AZ1: Total Fours | BA1: Total Sixes
A2: AC2025-01 | B2: 1st Match, Group B | C2: 45909 | D2: Afghanistan | E2: Hong Kong | F2: 188/6 (20) | G2: 188 | H2: 6 | I2: 20 | J2: 10 | K2: 0 | L2: 1 | M2: 9 | N2: 0 | O2: 41 | P2: 0.1-6 | Q2: 10 | R2: 5 | S2: Sediqullah Atal (73*) | T2: Fazalhaq Farooqi (2/16) | U2: Jonathan Trott | V2: Rahmanullah Gurbaz (wk), Sediqullah Atal, Ibrahim Zadran, Gulbadin Naib, Azmatullah Omarzai, Mohammad Nabi, Karim Janat, Rashid Khan (c), Noor Ahmad, AM Ghazanfar, Fazalhaq Farooqi | W2: Atal(73*/52/5/3), Gurbaz(8/5/1/0), Zadran(1/4/0/0), Nabi(33/26/3/2), Gulbadin(5/8/0/0), Azmatullah(53/21/2/5), Janat(2/3/0/0), R.Khan(3*/1/0/0) | X2: Farooqi(3-1-16-2), Azmatullah(2-0-4-1), Ghazanfar(2-0-4-0), R.Khan(4-0-24-1), Noor(4-0-16-1), Gulbadin(3-0-8-2), Janat(2-0-21-0) | Y2: 25-1(2.2), 26-2(3.2), 77-3(10.1), 95-4(12.6), 177-5(18.5), 184-6(19.4) | Z2: 94/9 (20) | AA2: 94 | AB2: 9 | AC2: 20 | AD2: 10 | AE2: 0 | AF2: 1 | AG2: 9 | AH2: 0 | AI2: 23 | AJ2: 0.1-6 | AK2: 6 | AL2: 2 | AM2: Babar Hayat (39) | AN2: Ayush Shukla (2/54) | AO2: Kaushal Silva | AP2: Zeeshan Ali (wk), Babar Hayat, Anshuman Rath, Kalhan Challu, Nizakat Khan, Aizaz Khan, Kinchit Shah, Yasim Murtaza (c), Ayush Shukla, Ateeq Iqbal, Ehsan Khan | AQ2: Z.Ali(5/6/1/0), Rath(0/1/0/0), Hayat(39/43/3/0), N.Khan(0/0/0/0), Challu(4/8/0/0), K.Shah(6/10/0/0), Murtaza(16/26/1/0), A.Khan(6/10/0/0), E.Khan(6/11/1/0), Shukla(1*/2/0/0), Iqbal(1*/3/0/0) | AR2: Shukla(4-0-54-2), Iqbal(3-0-32-1), E.Khan(4-0-28-1), A.Khan(2-0-26-2), Murtaza(4-0-23-0), K.Shah(3-0-24-2) | AS2: 1-1(0.2), 12-2(1.6), 13-3(2.2), 22-4(4.3), 43-5(9.5), 63-6(12.5), 78-7(16.2), 91-8(18.4), 93-9(19.2) | AT2: =4*Q2+6*R2 -> 70 | AU2: =4*AK2+6*AL2 -> 36 | AV2: =AT2/G2 -> 0.37234043 | AW2: =AU2/AA2 -> 0.38297872 | AX2: =G2/((INT(I2)*6+ROUND((I2-INT(I2))*10,0))/6) -> 9.4 | AY2: =AA2/((INT(AC2)*6+ROUND((AC2-INT(AC2))*10,0))/6) -> 4.7 | AZ2: =Q2+AK2 -> 16 | BA2: =R2+AL2 -> 7
A3: AC2025-02 | B3: 2nd Match, Group A | C3: 45910 | D3: United Arab Emirates | E3: India | F3: 57/10 (13.1) | G3: 57 | H3: 10 | I3: 13.1 | J3: 2 | K3: 0 | L3: 0 | M3: 2 | N3: 0 | O3: 41 | P3: 0.1-6 | Q3: 4 | R3: 1 | S3: Alishan Sharafu (22) | T3: Kuldeep Yadav (4/7) | U3: Lalchand Rajput | V3: Muhammad Waseem (c), Alishan Sharafu, Muhammad Zohaib, Rahul Chopra (wk), Asif Khan, Harshit Kaushik, Dhruv Parashar, Haider Ali, Muhammad Rohid Khan, Junaid Siddique, Simranjeet Singh | W3: Sharafu(22/17/3/1), Waseem(19/22/1/0), Zohaib(2/5/0/0), Chopra(3/7/0/0), A.Khan(2/7/0/0), Kaushik(2/2/0/0), Parashar(1/7/0/0), Singh(1/5/0/0), H.Ali(1/2/0/0), Siddique(0/3/0/0), R.Khan(2*/2/0/0) | X3: H.Ali(1-0-10-0), R.Khan(1-0-15-1), Parashar(1-0-13-1), Siddique(1-0-16-1), Singh(0.3-0-6-0) | Y3: 26-1(3.4), 29-2(4.4), 47-3(8.1), 48-4(8.4), 50-5(8.6), 51-6(10.3), 52-7(11.2), 54-8(12.1), 55-9(12.4), 57-10(13.1) | Z3: 60/1 (4.3) | AA3: 60 | AB3: 1 | AC3: 4.3 | AD3: 3 | AE3: 0 | AF3: 0 | AG3: 3 | AH3: 0 | AI3: 60 | AJ3: 0.1-6 | AK3: 8 | AL3: 2 | AM3: Abhishek Sharma (30) | AN3: Kuldeep Yadav (4/7) | AO3: Gautam Gambhir | AP3: Abhishek Sharma, Shubman Gill, Suryakumar Yadav (c), Tilak Varma, Sanju Samson (wk), Shivam Dube, Hardik Pandya, Axar Patel, Kuldeep Yadav, Jasprit Bumrah, Varun Chakaravarthy | AQ3: Sharma(30/16/3/2), Gill(20*/9/2/0), Yadav(7*/2/0/1) | AR3: Pandya(1-0-10-0), Bumrah(3-0-19-1), Axar(3-0-13-1), Varun(2-0-4-1), Kuldeep(2.1-0-7-4), Dube(2-0-4-3) | AS3: 48-1(3.5) | AT3: =4*Q3+6*R3 -> 22 | AU3: =4*AK3+6*AL3 -> 44 | AV3: =AT3/G3 -> 0.38596491 | AW3: =AU3/AA3 -> 0.73333333 | AX3: =G3/((INT(I3)*6+ROUND((I3-INT(I3))*10,0))/6) -> 4.3291139 | AY3: =AA3/((INT(AC3)*6+ROUND((AC3-INT(AC3))*10,0))/6) -> 13.333333 | AZ3: =Q3+AK3 -> 12 | BA3: =R3+AL3 -> 3
